<?xml version='1.0'?>
<robot name="dd_robot">

<!-- Base Link -->
<link name="base_link">
	<visual>
		<origin xyz="0 0 0" rpy="0 0 0" />
		<geometry>
			<box size="0.7 0.5 0.25"/>
		</geometry>
		<material name="blue">
			<color rgba="0 0.5 1 1"/>
		</material>
	</visual>
	<collision>
		<origin xyz="0 0 0" rpy="0 0 0" />
		<geometry>
			<box size="0.7 0.5 0.25"/>
		</geometry>
	</collision>
	<inertial>
		<mass value="5"/>
		<inertia ixx="0.13" ixy="0.0" ixz="0.0" iyy="0.21" iyz="0.0" izz="0.13"/>
	</inertial>


	<!-- Caster -->
	<visual name="caster">
		<material name="black">
			<color rgba="1 1 1 1"/>
		</material>
		<origin xyz="0.2 0 -0.125" rpy="0 0 0" />
		<geometry>
			<sphere radius="0.07" />
		</geometry>
	</visual>
	<collision>
		<origin xyz="0.2 0 -0.125" rpy="0 0 0" />
		<geometry>
			<sphere radius="0.07" />
		</geometry>
	</collision>
	<inertial>
		<mass value="0.5"/>
		<inertia ixx="0.0001" ixy="0.0" ixz="0.0" iyy="0.0001" iyz="0.0" izz="0.0001"/>
	</inertial>


</link>

<!-- Right Wheel -->
<link name="right_wheel">
	<visual>
		<material name="white">
			<color rgba="0 0 0 1"/>
		</material>
		<origin xyz="0 0 0" rpy="1.570795 0 0" />
		<geometry>
			<cylinder length="0.1" radius="0.2" />
		</geometry>
	</visual>
	<collision>
		<origin xyz="0 0 0" rpy="1.570795 0 0" />
		<geometry>
			<cylinder length="0.1" radius="0.2" />
		</geometry>
	</collision>
	<inertial>
		<mass value="0.5"/>
		<inertia ixx="0.01" ixy="0.0" ixz="0.0" iyy="0.005" iyz="0.0" izz="0.005"/>
	</inertial>

</link>
<joint name="joint_right_wheel" type="continuous">
	<parent link="base_link"/>
	<child link="right_wheel"/>
	<origin xyz="-0.2 -0.30 0" rpy="0 0 0" />
	<axis xyz="0 1 0" />
	<dynamics damping="0.7"/>
</joint>

<!-- Left Wheel -->
<link name="left_wheel">
	<visual>
	<material name="white"/>
	<origin xyz="0 0 0" rpy="1.570795 0 0" />
	<geometry>
		<cylinder length="0.1" radius="0.2" />
	</geometry>
	</visual>
	<collision>
		<origin xyz="0 0 0" rpy="1.570795 0 0" />
		<geometry>
			<cylinder length="0.1" radius="0.2" />
		</geometry>
	</collision>
	<inertial>
		<mass value="0.5"/>
		<inertia ixx="0.01" ixy="0.0" ixz="0.0" iyy="0.005" iyz="0.0" izz="0.005"/>
	</inertial>
</link>
<joint name="joint_left_wheel" type="continuous">
	<parent link="base_link"/>
	<child link="left_wheel"/>
	<origin xyz="-0.2 0.30 0" rpy="0 0 0" />
	<axis xyz="0 1 0" />
	<dynamics damping="0.7"/>
</joint>

<gazebo reference="base_link">
	<material>Gazebo/Blue</material>
</gazebo>
<gazebo reference="right_wheel">
	<material>Gazebo/Black</material>
</gazebo>
<gazebo reference="left_wheel">
	<material>Gazebo/Black</material>
</gazebo>


<gazebo>
  <plugin name="differential_drive_controller" filename="libgazebo_ros_diff_drive.so">
    <alwaysOn>true</alwaysOn>
    <updateRate>50</updateRate>
    <leftJoint>joint_left_wheel</leftJoint>
    <rightJoint>joint_right_wheel</rightJoint>
    <wheelSeparation>0.5</wheelSeparation>
    <wheelDiameter>0.2</wheelDiameter>
    <torque>15</torque>
    <commandTopic>cmd_vel</commandTopic>
    <odometryTopic>odom</odometryTopic>
    <odometryFrame>odom</odometryFrame>
    <robotBaseFrame>base_link</robotBaseFrame>
    <robotNamespace>ddrobot</robotNamespace>
  </plugin>
</gazebo>

</robot>

