<?xml version="1.0"?>
<robot name="nice_ride">

 <!--BASE-->
    <link name="base_link">

<inertial>
        <mass value="10"/>
        <inertia ixx="0.0159021" ixy="0" ixz="0" iyy="0.0159021" iyz="0" izz="0.0307567"/>
</inertial>

 <collision name='collision'>
         <geometry>
          <box size="0.8 0.6 0.1"/>
             <origin xyz="0 0 0.1"/>
        </geometry>
	
 </collision>

  <visual>

      <geometry>
        <box size="0.8 0.6 0.1"/>
      </geometry>
	<origin xyz="0 0 0.1"/>
  </visual>

  </link>
    <gazebo reference="base_link">
    <material>Gazebo/Blue</material>
    <turnGravityOff>false</turnGravityOff>
  </gazebo>

<!--HOLDER 1-->
<link name="holder1">

        <inertial>
      <mass value="1e-5" />
      <origin xyz="0 0 0" rpy="0 0 0"/>
      <inertia ixx="1e-6" ixy="0" ixz="0" iyy="1e-6" iyz="0" izz="1e-6" />
    </inertial>

    <collision name='collision'>

      <geometry>
        <box size="0.02 0.02 0.45"/>
      </geometry>
	<origin xyz="0 0 0" rpy="0 0 0"/>
   	<material name="black"/>
    </collision>

    <visual>

      <geometry>
        <box size="0.02 0.02 0.45"/>
      </geometry>
	<origin xyz="0 0 0" rpy="0 0 0"/>
	<material name="black"/>

    </visual>
</link>

<gazebo reference="holder1">
    <material>Gazebo/Black</material>
    <turnGravityOff>false</turnGravityOff>
</gazebo>

<joint name="holder1_joint" type="fixed">
    <axis xyz="0 1 0" />

    <origin rpy="0 0 0" xyz="0.39 0.26 0.375" />
    <parent link="base_link"/>
    <child link="holder1"/>
</joint>

<!--HOLDER 2-->
<link name="holder2">

        <inertial>
      <mass value="1e-5" />
      <origin xyz="0 0 0" rpy="0 0 0"/>
      <inertia ixx="1e-6" ixy="0" ixz="0" iyy="1e-6" iyz="0" izz="1e-6" />
    </inertial>

    <collision name='collision'>

      <geometry>
         <box size="0.02 0.02 0.45"/>
      </geometry>
	<origin xyz="0 0 0" rpy="0 0 0"/>
   	<material name="black"/>
    </collision>

    <visual>

      <geometry>
         <box size="0.02 0.02 0.45"/>
      </geometry>
	<origin xyz="0 0 0" rpy="0 0 0"/>
	<material name="black"/>

    </visual>
</link>

<gazebo reference="holder2">
    <material>Gazebo/Black</material>
    <turnGravityOff>false</turnGravityOff>
</gazebo>

<joint name="holder2_joint" type="fixed">
    <axis xyz="0 1 0" />
   <origin rpy="0 0 0" xyz="0.39 -0.26 0.375" />
    <parent link="base_link"/>
    <child link="holder2"/>
</joint>

<!--SQUARE PLATE-->

 <link name="square">

     <inertial>
          <mass value="1"/>
        <inertia ixx="0.145833" ixy="0" ixz="0" iyy="0.145833" iyz="0" izz="0.125"/>
</inertial>

<collision name='collision'>
         <geometry>
          <box size="0.02 0.5 0.5"/>
        </geometry>
        <origin rpy="0 0.78535 0" xyz="0 0 0"/>
	 <material name="green"/>
 </collision>


    <visual>
         <geometry>
          <box size="0.02 0.5 0.5"/>
        </geometry>
      <origin rpy="0 0.78535 0" xyz="0 0 0"/>
	 <material name="green"/>
    </visual>
  </link>
    <gazebo reference="square">
    <material>Gazebo/Green</material>
    <turnGravityOff>false</turnGravityOff>
  </gazebo>

  <joint name="base_to_square" type="fixed">
    <parent link="base_link"/>
    <child link="square"/>
   <origin rpy="0 0 0" xyz="0.39 0 0.6" />
      <axis xyz="0 1 0"/>

      <calibration rising="0.0"/>
      <dynamics damping="0.0" friction="0.0"/>

  </joint>
<!--.....................PSD1L...........-->

<link name="psd1l">

  <inertial>
      <mass value="1e-5" />
      <origin xyz="0 0 0" rpy="0 0 0"/>
      <inertia ixx="1e-6" ixy="0" ixz="0" iyy="1e-6" iyz="0" izz="1e-6" />
    </inertial>

    <collision name='collision'>

      <geometry>
        <box size="0.01 0.01 0.01"/>
      </geometry>
	<origin rpy="0 0 0" xyz="0 0 0"/>
   	<material name="yellow"/>
    </collision>

    <visual>

      <geometry>
        <box size="0.01 0.01 0.01"/>
      </geometry>
	<origin rpy="0 0 0" xyz="0 0 0"/>
	<material name="yellow"/>

    </visual>

</link>

<gazebo reference="psd1l">
    <material>Gazebo/Yellow</material>
    <turnGravityOff>false</turnGravityOff>
  </gazebo>

<joint name="psd1l_joint" type="fixed">
    <axis xyz="0 1 0" />
    <origin rpy="0 0.78535 0" xyz="0.1432 -0.1875 0.122" />  
    <parent link="square"/>
    <child link="psd1l"/>
</joint>


<!--  ........................................SENSOR PLUGIN.....................................-->
<gazebo reference="psd1l">
   <sensor type="ray" name="TeraRanger">
      <pose>0 0 0 0 0 0</pose>
      <visualize>true</visualize>
      <update_rate>50</update_rate>
      <ray>
         <scan>
            <horizontal>
               <samples>10</samples>
               <resolution>1</resolution>
               <min_angle>-0.2618</min_angle>
               <max_angle>0.2618</max_angle>
            </horizontal>
            <vertical>
               <samples>10</samples>
               <resolution>1</resolution>
               <min_angle>-0.2618</min_angle>
               <max_angle>0.2618</max_angle>
            </vertical>
         </scan>
         <range>
            <min>0.02</min>
            <max>4</max>
            <resolution>0.02</resolution>
         </range>
      </ray>
      <plugin filename="libgazebo_ros_range.so" name="gazebo_ros_range5">
         <gaussianNoise>0.005</gaussianNoise>
         <alwaysOn>true</alwaysOn>
         <updateRate>50</updateRate>
         <topicName>psd1l_topic</topicName>
         <frameName>psd1l</frameName>
         <radiation>ultrasound</radiation>
         <fov>0.2967</fov>
      </plugin>
   </sensor>
   </gazebo>

<!--.....................PSD1R...........-->

<link name="psd1r">

  <inertial>
      <mass value="1e-5" />
      <origin xyz="0 0 0" rpy="0 0 0"/>
      <inertia ixx="1e-6" ixy="0" ixz="0" iyy="1e-6" iyz="0" izz="1e-6" />
    </inertial>

    <collision name='collision'>

      <geometry>
        <box size="0.01 0.01 0.01"/>
      </geometry>
	<origin rpy="0 0 0" xyz="0 0 0"/>
   	<material name="yellow"/>
    </collision>

    <visual>

      <geometry>
        <box size="0.01 0.01 0.01"/>
      </geometry>
	<origin rpy="0 0 0" xyz="0 0 0"/>
	<material name="yellow"/>

    </visual>

</link>

<gazebo reference="psd1r">
    <material>Gazebo/Yellow</material>
    <turnGravityOff>false</turnGravityOff>
  </gazebo>

<joint name="psd1r_joint" type="fixed">
    <axis xyz="0 1 0" />
    <origin rpy="0 0.78535 0" xyz="0.1432 0.1875 0.122" />
    <parent link="square"/>
    <child link="psd1r"/>
</joint>


<!--  ........................................SENSOR PLUGIN.....................................-->
<gazebo reference="psd1r">
   <sensor type="ray" name="TeraRanger">
      <pose>0 0 0 0 0 0</pose>
      <visualize>true</visualize>
      <update_rate>50</update_rate>
      <ray>
         <scan>
            <horizontal>
               <samples>10</samples>
               <resolution>1</resolution>
               <min_angle>-0.2618</min_angle>
               <max_angle>0.2618</max_angle>
            </horizontal>
            <vertical>
               <samples>10</samples>
               <resolution>1</resolution>
               <min_angle>-0.2618</min_angle>
               <max_angle>0.2618</max_angle>
            </vertical>
         </scan>
         <range>
            <min>0.02</min>
            <max>4</max>
            <resolution>0.02</resolution>
         </range>
      </ray>
      <plugin filename="libgazebo_ros_range.so" name="gazebo_ros_range6">
         <gaussianNoise>0.005</gaussianNoise>
         <alwaysOn>true</alwaysOn>
         <updateRate>50</updateRate>
         <topicName>psd1r_topic</topicName>
         <frameName>psd1r</frameName>
         <radiation>ultrasound</radiation>
         <fov>0.2967</fov>
      </plugin>
   </sensor>
   </gazebo>


<!--.....................PSD2L...........-->

<link name="psd2l">

  <inertial>
      <mass value="1e-5" />
      <origin xyz="0 0 0" rpy="0 0 0"/>
      <inertia ixx="1e-6" ixy="0" ixz="0" iyy="1e-6" iyz="0" izz="1e-6" />
    </inertial>

    <collision name='collision'>

      <geometry>
        <box size="0.01 0.01 0.01"/>
      </geometry>
	<origin rpy="0 0 0" xyz="0 0 0"/>
   	<material name="yellow"/>
    </collision>

    <visual>

      <geometry>
        <box size="0.01 0.01 0.01"/>
      </geometry>
	<origin rpy="0 0 0" xyz="0 0 0"/>
	<material name="yellow"/>

    </visual>

</link>

<gazebo reference="psd2l">
    <material>Gazebo/Yellow</material>
    <turnGravityOff>false</turnGravityOff>
  </gazebo>

<joint name="psd2l_joint" type="fixed">
    <axis xyz="0 1 0" />
    <origin rpy="0 0.78535 0" xyz="0.0106 -0.1875 -0.0106" /> 
    <parent link="square"/>
    <child link="psd2l"/>
</joint>


<!--  ........................................SENSOR PLUGIN.....................................-->
<gazebo reference="psd2l">
   <sensor type="ray" name="TeraRanger">
      <pose>0 0 0 0 0 0</pose>
      <visualize>true</visualize>
      <update_rate>50</update_rate>
      <ray>
         <scan>
            <horizontal>
               <samples>10</samples>
               <resolution>1</resolution>
               <min_angle>-0.2618</min_angle>
               <max_angle>0.2618</max_angle>
            </horizontal>
            <vertical>
               <samples>10</samples>
               <resolution>1</resolution>
               <min_angle>-0.2618</min_angle>
               <max_angle>0.2618</max_angle>
            </vertical>
         </scan>
         <range>
            <min>0.02</min>
            <max>4</max>
            <resolution>0.02</resolution>
         </range>
      </ray>
      <plugin filename="libgazebo_ros_range.so" name="gazebo_ros_range7">
         <gaussianNoise>0.005</gaussianNoise>
         <alwaysOn>true</alwaysOn>
         <updateRate>50</updateRate>
         <topicName>psd2l_topic</topicName>
         <frameName>psd2l</frameName>
         <radiation>ultrasound</radiation>
         <fov>0.2967</fov>
      </plugin>
   </sensor>
   </gazebo>

<!--.....................PSD2R...........-->

<link name="psd2r">

  <inertial>
      <mass value="1e-5" />
      <origin xyz="0 0 0" rpy="0 0 0"/>
      <inertia ixx="1e-6" ixy="0" ixz="0" iyy="1e-6" iyz="0" izz="1e-6" />
    </inertial>

    <collision name='collision'>

      <geometry>
        <box size="0.01 0.01 0.01"/>
      </geometry>
	<origin rpy="0 0 0" xyz="0 0 0"/>
   	<material name="yellow"/>
    </collision>

    <visual>

      <geometry>
        <box size="0.01 0.01 0.01"/>
      </geometry>
	<origin rpy="0 0 0" xyz="0 0 0"/>
	<material name="yellow"/>

    </visual>

</link>

<gazebo reference="psd2r">
    <material>Gazebo/Yellow</material>
    <turnGravityOff>false</turnGravityOff>
  </gazebo>

<joint name="psd2r_joint" type="fixed">
    <axis xyz="0 1 0" />
    <origin rpy="0 0.78535 0" xyz="0.0106 0.1875 -0.0106" />
    <parent link="square"/>
    <child link="psd2r"/>
</joint>
<!--  ........................................SENSOR PLUGIN.....................................-->
<gazebo reference="psd2r">
   <sensor type="ray" name="TeraRanger">
      <pose>0 0 0 0 0 0</pose>
      <visualize>true</visualize>
      <update_rate>50</update_rate>
      <ray>
         <scan>
            <horizontal>
               <samples>10</samples>
               <resolution>1</resolution>
               <min_angle>-0.2618</min_angle>
               <max_angle>0.2618</max_angle>
            </horizontal>
            <vertical>
               <samples>10</samples>
               <resolution>1</resolution>
               <min_angle>-0.2618</min_angle>
               <max_angle>0.2618</max_angle>
            </vertical>
         </scan>
         <range>
            <min>0.02</min>
            <max>4</max>
            <resolution>0.02</resolution>
         </range>
      </ray>
      <plugin filename="libgazebo_ros_range.so" name="gazebo_ros_range8">
         <gaussianNoise>0.005</gaussianNoise>
         <alwaysOn>true</alwaysOn>
         <updateRate>50</updateRate>
         <topicName>psd2r_topic</topicName>
         <frameName>psd2r</frameName>
         <radiation>ultrasound</radiation>
         <fov>0.2967</fov>
      </plugin>
   </sensor>
   </gazebo>

<!--RIGHT WHEEL-->

 <link name="right_leg">

     <inertial>
          <mass value="1"/>
        <inertia ixx="0.145833" ixy="0" ixz="0" iyy="0.145833" iyz="0" izz="0.125"/>
</inertial>

<collision name='collision'>
         <geometry>
         <cylinder length="0.1" radius="0.1"/>
        </geometry>
        <origin rpy="-1.5707 -1.5707 0" xyz="0 0 0"/>
	 <material name="black"/>
 </collision>


    <visual>
      <geometry>
         <cylinder length="0.1" radius="0.1"/>
      </geometry>
      <origin rpy="-1.5707 -1.5707 0" xyz="0 0 0"/>
	 <material name="black"/>
    </visual>
  </link>
    <gazebo reference="right_leg">
    <material>Gazebo/Black</material>
    <turnGravityOff>false</turnGravityOff>
  </gazebo>

  <joint name="base_to_right_leg" type="continuous">
    <parent link="base_link"/>
    <child link="right_leg"/>
    <origin xyz="-0.3 0.35 0"/>
      <axis xyz="0 1 0"/>

      <calibration rising="0.0"/>
      <dynamics damping="0.0" friction="0.0"/>

  </joint>


    <!--LEFT WHEEL-->
<link name="left_leg">

    <inertial>
        <mass value="1"/>
        <inertia ixx="0.145833" ixy="0" ixz="0" iyy="0.145833" iyz="0" izz="0.125"/>
</inertial>

<collision name='collision'>
         <geometry>
         <cylinder length="0.1" radius="0.1"/>
        </geometry>
      <origin rpy="-1.5707 -1.5707 0" xyz="0 0 0"/>
	 <material name="black"/>
 </collision>

    <visual>
      <geometry>
         <cylinder length="0.1" radius="0.1"/>
      </geometry>
      <origin rpy="-1.5707 -1.5707 0" xyz="0 0 0"/>
	 <material name="black"/>
    </visual>
  </link>
    <gazebo reference="left_leg">
    <material>Gazebo/Black</material>
    <turnGravityOff>false</turnGravityOff>
  </gazebo>

  <joint name="base_to_left_leg" type="continuous">
    <parent link="base_link"/>
    <child link="left_leg"/>
    <origin xyz="-0.3 -0.35 0"/>
      <axis xyz="0 1 0"/>

      <calibration rising="0.0"/>
      <dynamics damping="0.0" friction="0.0"/>


  </joint>

    <!--LEFT FRONT WHEEL-->
<link name="left_front_leg">

    <inertial>
        <mass value="1"/>
        <inertia ixx="0.145833" ixy="0" ixz="0" iyy="0.145833" iyz="0" izz="0.125"/>
</inertial>

<collision name='collision'>
         <geometry>
         <cylinder length="0.1" radius="0.1"/>
        </geometry>
     <origin rpy="-1.5707 -1.5707 0" xyz="0 0 0"/>
	 <material name="black"/>
 </collision>

    <visual>
      <geometry>
         <cylinder length="0.1" radius="0.1"/>
      </geometry>
      <origin rpy="-1.5707 -1.5707 0" xyz="0 0 0"/>
	 <material name="black"/>
    </visual>
  </link>
    <gazebo reference="left_front_leg">
    <material>Gazebo/Black</material>
    <turnGravityOff>false</turnGravityOff>
  </gazebo>

  <joint name="base_to_left_front_leg" type="continuous">
    <parent link="base_link"/>
    <child link="left_front_leg"/>
    <origin xyz="0.3 -0.35 0"/>
      <axis xyz="0 1 0"/>

      <calibration rising="0.0"/>
      <dynamics damping="0.0" friction="0.0"/>

  </joint>

     <!--RIGHT FRONT WHEEL-->
<link name="right_front_leg">

    <inertial>
        <mass value="1"/>
        <inertia ixx="0.145833" ixy="0" ixz="0" iyy="0.145833" iyz="0" izz="0.125"/>
</inertial>

<collision name='collision'>
         <geometry>
         <cylinder length="0.1" radius="0.1"/>
        </geometry>
      <origin rpy="-1.5707 -1.5707 0" xyz="0 0 0"/>
	 <material name="black"/>
 </collision>
    <visual>

      <geometry>
         <cylinder length="0.1" radius="0.1"/>
      </geometry>
      <origin rpy="-1.5707 -1.5707 0" xyz="0 0 0"/>
	 <material name="black"/>
    </visual>
  </link>

    <gazebo reference="right_front_leg">
    <material>Gazebo/Black</material>
    <turnGravityOff>false</turnGravityOff>
  </gazebo>

  <joint name="base_to_right_front_leg" type="continuous">
    <parent link="base_link"/>
    <child link="right_front_leg"/>
    <origin xyz="0.3 0.35 0"/>
      <axis xyz="0 1 0"/>

      <calibration rising="0.0"/>
      <dynamics damping="0.0" friction="0.0"/>

  </joint>



<!--..............................................IMU SENSOR...........................................-->
<link name="base_imu_front">

        <inertial>
      <mass value="1e-5" />
      <origin xyz="0 0 0" rpy="0 0 0"/>
      <inertia ixx="1e-6" ixy="0" ixz="0" iyy="1e-6" iyz="0" izz="1e-6" />
    </inertial>

    <collision name='collision'>

      <geometry>
        <box size="0.01 0.01 0.01"/>
      </geometry>
	<origin xyz="0 0 0" rpy="0 0 0"/>
   	<material name="black"/>
    </collision>

    <visual>

      <geometry>
        <box size="0.01 0.01 0.01"/>
      </geometry>
	<origin xyz="0 0 0" rpy="0 0 0"/>
	<material name="black"/>

    </visual>
</link>

<gazebo reference="base_imu_front">
    <material>Gazebo/Black</material>
    <turnGravityOff>false</turnGravityOff>
</gazebo>

<joint name="imu_front_joint" type="fixed">
    <axis xyz="0 1 0" />
    <origin rpy="0 0 0" xyz="-0.2 0 0.155" />
    <parent link="base_link"/>
    <child link="base_imu_front"/>
</joint>

<!--....................................PLUGIN.........................................-->
<gazebo>
    <plugin name="imu_plugin" filename="libgazebo_ros_imu.so">
        <alwaysOn>true</alwaysOn>
        <bodyName>base_imu_front</bodyName>
        <topicName>imu_data</topicName>
        <serviceName>imu_service</serviceName>
        <gaussianNoise>0.0</gaussianNoise>
        <updateRate>50</updateRate>
    </plugin>
</gazebo>

<!--..................................................................................-->


<!--...................................GPS MODULE...................................................-->
<link name="base_gps_front">

        <inertial>
      <mass value="1e-5" />
      <origin xyz="0 0 0" rpy="0 0 0"/>
      <inertia ixx="1e-6" ixy="0" ixz="0" iyy="1e-6" iyz="0" izz="1e-6" />
    </inertial>

    <collision name='collision'>

      <geometry>
        <box size="0.01 0.01 0.01"/>
      </geometry>
	<origin xyz="0 0 0" rpy="0 0 0"/>
   	<material name="green"/>
    </collision>

    <visual>

      <geometry>
        <box size="0.01 0.01 0.01"/>
      </geometry>
	<origin xyz="0 0 0" rpy="0 0 0"/>
	<material name="green"/>

    </visual>
</link>

<gazebo reference="base_gps_front">
    <material>Gazebo/Green</material>
    <turnGravityOff>false</turnGravityOff>
</gazebo>

<joint name="gps_front_joint" type="fixed">
    <axis xyz="0 1 0" />
    <origin rpy="0 0 0" xyz="-0.395 -0.295 0.155" />
    <parent link="base_link"/>
    <child link="base_gps_front"/>
</joint>

<!--..................................GPS SENSOR PLUGIN.......................................-->

    <!-- GPS Sensor -->
  <gazebo>
    <plugin name="novatel_gps_sim" filename="libhector_gazebo_ros_gps.so">
      <alwaysOn>1</alwaysOn>
      <updateRate>50</updateRate>
      <bodyName>base_gps_front</bodyName>
      <topicName>gps_topic</topicName>
      <velocityTopicName>gps_velocity</velocityTopicName>
      <drift>5.0 5.0 5.0</drift>
      <gaussianNoise>0.1 0.1 0.1</gaussianNoise>
      <velocityDrift>0 0 0</velocityDrift>
      <velocityGaussianNoise>0.1 0.1 0.1</velocityGaussianNoise>
      <heading_deg>90</heading_deg> 
    </plugin>
  </gazebo>

<!--...................................CAMERA MODULE...................................................-->
<link name="base_camera_front">

        <inertial>
      <mass value="1e-5" />
      <origin xyz="0 0 0" rpy="0 0 0"/>
      <inertia ixx="1e-6" ixy="0" ixz="0" iyy="1e-6" iyz="0" izz="1e-6" />
    </inertial>

    <collision name='collision'>

      <geometry>
        <box size="0.01 0.01 0.01"/>
      </geometry>
	<origin xyz="0 0 0" rpy="0 0 0"/>
   	<material name="white"/>
    </collision>

    <visual>

      <geometry>
        <box size="0.01 0.01 0.01"/>
      </geometry>
	<origin xyz="0 0 0" rpy="0 0 0"/>
	<material name="white"/>

    </visual>
</link>

<gazebo reference="base_camera_front">
    <material>Gazebo/White</material>
    <turnGravityOff>false</turnGravityOff>
</gazebo>

<joint name="camera_front_joint" type="fixed">
    <axis xyz="0 1 0" />
    <origin rpy="0 0 0" xyz="0.405 0 0.145" />
    <parent link="base_link"/>
    <child link="base_camera_front"/>
</joint>

<!--..................................SENSOR PLUGIN.........................................-->
<!-- camera -->
  <gazebo reference="base_camera_front">
    <sensor type="camera" name="camera1">
      <update_rate>30.0</update_rate>
      <camera name="head">
        <horizontal_fov>1.3962634</horizontal_fov>
        <image>
          <width>800</width>
          <height>800</height>
          <format>R8G8B8</format>
        </image>
        <clip>
          <near>0.02</near>
          <far>300</far>
        </clip>
        <noise>
          <type>gaussian</type>
          <!-- Noise is sampled independently per pixel on each frame.
               That pixel's noise value is added to each of its color
               channels, which at that point lie in the range [0,1]. -->
          <mean>0.0</mean>
          <stddev>0.007</stddev>
        </noise>
      </camera>
      <plugin name="camera_controller" filename="libgazebo_ros_camera.so">
        <alwaysOn>true</alwaysOn>
        <updateRate>0.0</updateRate>
        <cameraName>rrbot/camera1</cameraName>
        <imageTopicName>image_raw</imageTopicName>
        <cameraInfoTopicName>camera_info</cameraInfoTopicName>
        <frameName>camera_link</frameName>
        <hackBaseline>0.07</hackBaseline>
        <distortionK1>0.0</distortionK1>
        <distortionK2>0.0</distortionK2>
        <distortionK3>0.0</distortionK3>
        <distortionT1>0.0</distortionT1>
        <distortionT2>0.0</distortionT2>
      </plugin>
    </sensor>
  </gazebo>


<!--.................................2D LIDAR.......................................-->

<link name="base_lidar_front">

        <inertial>
      <mass value="1e-5" />
      <origin xyz="0 0 0" rpy="0 0 0"/>
      <inertia ixx="1e-6" ixy="0" ixz="0" iyy="1e-6" iyz="0" izz="1e-6" />
    </inertial>

    <collision name='collision'>

      <geometry>
        <box size="0.01 0.01 0.01"/>
      </geometry>
	<origin xyz="0 0 0" rpy="0 0 0"/>
   	<material name="red"/>
    </collision>

    <visual>

      <geometry>
        <box size="0.01 0.01 0.01"/>
      </geometry>
	<origin xyz="0 0 0" rpy="0 0 0"/>
	<material name="red"/>

    </visual>
</link>

<gazebo reference="base_lidar_front">
    <material>Gazebo/Red</material>
    <turnGravityOff>false</turnGravityOff>
</gazebo>

<joint name="lidar_front_joint" type="fixed">
    <axis xyz="0 1 0" />
    <origin rpy="0 0 0" xyz="0 0 0.155" />
    <parent link="base_link"/>
    <child link="base_lidar_front"/>
</joint>

<!--.................................SENSOR PLUGIN.....................................-->

  <gazebo reference="base_lidar_front">
    <sensor type="ray" name="lidar">
      <pose>0 0 0 0 0 0</pose>
      <visualize>false</visualize>
      <update_rate>50</update_rate>
      <ray>
         <scan>
            <horizontal>
               <samples>11</samples>    <!--180/10-->
               <resolution>1</resolution>
               <min_angle>-1.570795</min_angle>
               <max_angle>1.570795</max_angle>
            </horizontal>
            <vertical>
               <samples>1</samples>
               <resolution>1</resolution> 
          <max_angle>0.14835</max_angle>
          <min_angle>0</min_angle>
            </vertical>
         </scan>
         <range>
            <min>0.1</min>
            <max>3.0</max>
            <resolution>0.01</resolution>
         </range>
      </ray>
      <plugin filename="libgazebo_ros_laser.so" name="gazebo_lidar">
         <gaussianNoise>0.005</gaussianNoise>
         <alwaysOn>true</alwaysOn>
         <update_rate>50</update_rate>
         <updateRateHZ>10.0</updateRateHZ>
         <topicName>lidar</topicName>
         <frameName>base_lidar_front</frameName>
      </plugin>
   </sensor>
  </gazebo>





<!--.................................DIFFERENTIAL DRIVES..........................................-->

<gazebo>
  <plugin name="differential_drive_controller1" filename="libgazebo_ros_diff_drive.so">
    <alwaysOn>true</alwaysOn>
    <updateRate>50</updateRate>
    <leftJoint>base_to_left_leg</leftJoint>
    <rightJoint>base_to_right_leg</rightJoint>
    <wheelSeparation>0.6</wheelSeparation>
    <wheelDiameter>0.2</wheelDiameter>
    <torque>30</torque>
    <commandTopic>champ</commandTopic>
    <odometryTopic>odom</odometryTopic>
    <odometryFrame>odom</odometryFrame>
    <robotBaseFrame>base_footprint</robotBaseFrame>
  </plugin>
</gazebo>

    <gazebo>
  <plugin name="differential_drive_controller2" filename="libgazebo_ros_diff_drive.so">
    <alwaysOn>true</alwaysOn>
    <updateRate>50</updateRate>
    <leftJoint>base_to_left_front_leg</leftJoint>
    <rightJoint>base_to_right_front_leg</rightJoint>
    <wheelSeparation>0.6</wheelSeparation>
    <wheelDiameter>0.2</wheelDiameter>
    <torque>30</torque>
    <commandTopic>champ</commandTopic>
    <odometryTopic>odom</odometryTopic>
    <odometryFrame>odom</odometryFrame>
    <robotBaseFrame>base_footprint</robotBaseFrame>
  </plugin>
</gazebo>



</robot>
