<?xml version="1.0"?>
<robot name="nice_ride">
  <link name="base_link">

<inertial>
        <mass value="0.18454"/>
        <inertia ixx="0.0159021" ixy="0" ixz="0" iyy="0.0159021" iyz="0" izz="0.0307567"/>
</inertial>

 <collision name='collision'>
         <geometry>
          <box size="0.8 0.6 0.1"/>
        </geometry>
 </collision>

  <visual>

      <geometry>
        <box size="0.8 0.6 0.1"/>
      </geometry>
	<origin xyz="0 0 0.1"/>
  </visual>

  </link>

<gazebo reference="right_leg">
  <material>Gazebo/Black</material>
</gazebo>


 <link name="right_leg">

     <inertial>
          <mass value="1"/>
        <inertia ixx="0.145833" ixy="0" ixz="0" iyy="0.145833" iyz="0" izz="0.125"/>
</inertial>

<collision name='collision'>
         <geometry>

         <cylinder length="0.1" radius="0.1"/>
        </geometry>
 </collision>


    <visual>
      <geometry>
         <cylinder length="0.1" radius="0.1"/>
      </geometry>
      <origin rpy="-1.5707 -1.5707 0" xyz="0 0 0"/>
	 <material name="black"/>
    </visual>
  </link>

  <joint name="base_to_right_leg" type="continuous">
    <parent link="base_link"/>
    <child link="right_leg"/>
    <origin xyz="-0.3 0.3 0"/>

      <calibration rising="0.0"/>
      <dynamics damping="0.0" friction="0.0"/>

  </joint>

<gazebo reference="left_leg">
  <material>Gazebo/Black</material>
</gazebo>


<link name="left_leg">

    <inertial>
        <mass value="1"/>
        <inertia ixx="0.145833" ixy="0" ixz="0" iyy="0.145833" iyz="0" izz="0.125"/>
</inertial>

<collision name='collision'>
         <geometry>

         <cylinder length="0.1" radius="0.1"/>
        </geometry>
 </collision>

    <visual>
      <geometry>
         <cylinder length="0.1" radius="0.1"/>
      </geometry>
      <origin rpy="-1.5707 -1.5707 0" xyz="0 0 0"/>
	 <material name="black"/>
    </visual>
  </link>

  <joint name="base_to_left_leg" type="continuous">
    <parent link="base_link"/>
    <child link="left_leg"/>
    <origin xyz="-0.3 -0.3 0"/>

      <calibration rising="0.0"/>
      <dynamics damping="0.0" friction="0.0"/>


  </joint>

<gazebo reference="left_front_leg">
  <material>Gazebo/Black</material>
</gazebo>


<link name="left_front_leg">

    <inertial>
        <mass value="1"/>
        <inertia ixx="0.145833" ixy="0" ixz="0" iyy="0.145833" iyz="0" izz="0.125"/>
</inertial>

<collision name='collision'>
         <geometry>

         <cylinder length="0.1" radius="0.1"/>
        </geometry>
 </collision>
    <visual>
      <geometry>
         <cylinder length="0.1" radius="0.1"/>
      </geometry>
      <origin rpy="-1.5707 -1.5707 0" xyz="0 0 0"/>
	 <material name="black"/>
    </visual>
  </link>

  <joint name="base_to_left_front_leg" type="continuous">
    <parent link="base_link"/>
    <child link="left_front_leg"/>
    <origin xyz="0.3 -0.3 0"/>
      <calibration rising="0.0"/>
      <dynamics damping="0.0" friction="0.0"/>

  </joint>

<gazebo reference="right_front_leg">
  <material>Gazebo/Black</material>
</gazebo>

<link name="right_front_leg">

    <inertial>
        <mass value="1"/>
        <inertia ixx="0.145833" ixy="0" ixz="0" iyy="0.145833" iyz="0" izz="0.125"/>
</inertial>

<collision name='collision'>
         <geometry>

         <cylinder length="0.1" radius="0.1"/>
        </geometry>
 </collision>
    <visual>

      <geometry>
         <cylinder length="0.1" radius="0.1"/>
      </geometry>
      <origin rpy="-1.5707 -1.5707 0" xyz="0 0 0"/>
	 <material name="black"/>
    </visual>
  </link>

  <joint name="base_to_right_front_leg" type="continuous">
    <parent link="base_link"/>
    <child link="right_front_leg"/>
    <origin xyz="0.3 0.3 0"/>

      <calibration rising="0.0"/>
      <dynamics damping="0.0" friction="0.0"/>

  </joint>


</robot>
